<?xml version='1.0'?>
<robot name="glide_robot">
  <link name="link_3">
  <origin xyz="-0.5 0.4 0" rpy=" 0 -0 0"/>
    <inertial>
      <mass value="1.0" />
      <origin xyz="-0.45 -0.00124 -0.113487" rpy="0 -0 0" />
      <inertia ixx="0.346215" ixy="0.0" ixz="0.0" iyy="0.548713" iyz="0.0" izz="0.535836" />
    </inertial>
    <visual>
      <origin xyz="-0.9 -0.00248 -0.226975" rpy="0.0 -0.0 0.0" />
      <geometry>
        <box size="0.2 0.2 0.2" />
      </geometry>
    </visual>
    <visual>
      <origin xyz="-0.5 0.0 0.0" rpy="0.0 -0.0 0.0" />
      <geometry>
        <box size="1.0 0.2 0.25" />
      </geometry>
    </visual>
    <collision>
      <origin xyz="-0.5 0.0 0.0" rpy="0.0 -0.0 0.0" />
      <geometry>
        <box size="0.95 0.2 0.25" />
      </geometry>
    </collision>
    <collision>
      <origin xyz="-0.9 -0.00248 -0.226975" rpy="0.0 -0.0 0.0" />
      <geometry>
        <box size="0.2 0.2 0.2" />
      </geometry>
    </collision>
  </link>
  <link name="link_2">
  <origin xyz="-1.39994 0.397228 -0.339814" rpy="-0.005156 -0.001069 -0.015992" />
    <inertial>
      <mass value="0.5" />
      <origin xyz="0.0 0.0 0.0" rpy="0 -0 0" />
      <inertia ixx="0.145833" ixy="0.0" ixz="0.0" iyy="0.145833" iyz="0.0" izz="0.125" />
    </inertial>
    <visual>
      <origin xyz="0.0 0.0 0.0" rpy="0 -0.0 -0.0" />
      <geometry>
        <cylinder radius="0.01" length="0.025" />
      </geometry>
    </visual>
    <collision>
      <origin xyz="0.0 0.0 0.0" rpy="0 -0.0 -0.0" />
      <geometry>
        <cylinder radius="0.01" length="0.025" />
      </geometry>
    </collision>
  </link>
  <link name="link_7">
  <origin xyz="-1.39989 0.396937 -0.452529" rpy="0 -0 0"/>
    <inertial>
      <mass value="0.5" />
      <origin xyz="0.0 0.0 0.0" rpy="0 -0 0" />
      <inertia ixx="0.145833" ixy="0.0" ixz="0.0" iyy="0.145833" iyz="0.0" izz="0.125" />
    </inertial>
    <visual>
      <origin xyz="0.0 0.0 0.0" rpy="1.5708 -0.0 0.0" />
      <geometry>
        <cylinder radius="0.1" length="0.1" />
      </geometry>
    </visual>
    <collision>
      <origin xyz="0.0 0.0 0.0" rpy="1.5708 -0.0 0.0" />
      <geometry>
        <cylinder radius="0.1" length="0.1" />
      </geometry>
    </collision>
  </link>
  <link name="link_4">
  <origin xyz="-0.5 -0.4 -0" rpy="0 -0 0" />
    <inertial>
      <mass value="1.0" />
      <origin xyz="-0.450002 0.0 -0.1125" rpy="0 -0 0" />
      <inertia ixx="0.34599" ixy="-0.0" ixz="0.0" iyy="0.548492" iyz="-0.0" izz="0.535836" />
    </inertial>
    <visual>
      <origin xyz="-0.900004 0.0 -0.225" rpy="0.0 -0.0 0.0" />
      <geometry>
        <box size="0.2 0.2 0.2" />
      </geometry>
    </visual>
    <visual>
      <origin xyz="-0.5 0.0 0.0" rpy="0.0 -0.0 0.0" />
      <geometry>
        <box size="1.0 0.2 0.25" />
      </geometry>
    </visual>
    <collision>
      <origin xyz="-0.5 0.0 0.0" rpy="0.0 -0.0 0.0" />
      <geometry>
        <box size="0.95 0.2 0.25" />
      </geometry>
    </collision>
    <collision>
      <origin xyz="-0.900004 0.0 -0.225" rpy="0.0 -0.0 0.0" />
      <geometry>
        <box size="0.2 0.2 0.2" />
      </geometry>
    </collision>
  </link>
  <link name="link_1">
  <origin xyz="0-1.39995 -0.400292 -0.337839" rpy="-0.005156 -0.001069 -0.015992" />
    <inertial>
      <mass value="0.5" />
      <origin xyz="0.0 0.0 0.0" rpy="0 -0 0" />
      <inertia ixx="0.145833" ixy="0.0" ixz="0.0" iyy="0.145833" iyz="0.0" izz="0.125" />
    </inertial>

    <visual>
      <origin xyz="0.0 0.0 0.0" rpy="0 -0.0 -0.0" />
      <geometry>
        <cylinder radius="0.01" length="0.025" />
      </geometry>
    </visual>
    <collision>
      <origin xyz="0.0 0.0 0.0" rpy="0 -0.0 -0.0" />
      <geometry>
        <cylinder radius="0.01" length="0.025" />
      </geometry>
    </collision>
  </link>

  <link name="link_5">
  <origin xyz="-1.39989 -0.400583 -0.450554" rpy="0 -0 0" />
    <inertial>
      <mass value="0.5" />
      <origin xyz="0.0 0.0 0.0" rpy="0 -0 0" />
      <inertia ixx="0.145833" ixy="0.0" ixz="0.0" iyy="0.145833" iyz="0.0" izz="0.125" />
    </inertial>
    <visual>
      <origin xyz="0.0 0.0 0.0" rpy="1.5708 -0.0 0.0" />
      <geometry>
        <cylinder radius="0.1" length="0.1" />
      </geometry>
    </visual>
    <collision>
      <origin xyz="0.0 0.0 0.0" rpy="1.5708 -0.0 0.0" />
      <geometry>
        <cylinder radius="0.1" length="0.1" />
      </geometry>
    </collision>
  </link>
  <link name="link_6">
  <origin xyz="0.400113 -0.000583 -0.450616" rpy="0 -0 0" />
    <inertial>
      <mass value="0.5" />
      <origin xyz="0.0 0.0 0.0" rpy="0 -0 0" />
      <inertia ixx="0.145833" ixy="0.0" ixz="0.0" iyy="0.145833" iyz="0.0" izz="0.125" />
    </inertial>
    <visual>
      <origin xyz="0.0 0.0 0.0" rpy="1.5708 -0.0 0.0" />
      <geometry>
        <cylinder radius="0.1" length="0.1" />
      </geometry>
    </visual>
    <collision>
      <origin xyz="0.0 0.0 0.0" rpy="1.5708 -0.0 0.0" />
      <geometry>
        <cylinder radius="0.1" length="0.1" />
      </geometry>
    </collision>
  </link>
  <link name="link_0">
    <inertial>
      <mass value="1.5" />
      <origin xyz="0.266686 -9.7e-05 -0.187623" rpy="0 -0 0" />
      <inertia ixx="0.508754" ixy="1.97065e-05" ixz="0.0375591" iyy="0.562093" iyz="-0.000183697" izz="0.511676" />
    </inertial>
    <visual>
      <origin xyz="0.0 0.0 0.0" rpy="0.0 -0.0 0.0" />
      <geometry>
        <box size="1.0 1.0 0.25" />
      </geometry>
    </visual>
    <visual>
      <origin xyz="0.4 0.0 -0.225" rpy="0.0 -0.0 0.0" />
      <geometry>
        <box size="0.2 0.2 0.2" />
      </geometry>
    </visual>
    <visual>
      <origin xyz="0.400057 -0.000292 -0.33787" rpy="-0.007728 -0.001634 -0.023986" />
      <geometry>
        <cylinder radius="0.01" length="0.025" />
      </geometry>
    </visual>
    <collision>
      <origin xyz="0.0 0.0 0.0" rpy="0.0 -0.0 0.0" />
      <geometry>
        <box size="1.0 1.0 0.25" />
      </geometry>
    </collision>
    <collision>
      <origin xyz="0.4 0.0 -0.225" rpy="0.0 -0.0 0.0" />
      <geometry>
        <box size="0.2 0.2 0.2" />
      </geometry>
    </collision>
    <collision>
      <origin xyz="0.400057 -0.000292 -0.33787" rpy="-0.007728 -0.001634 -0.023986" />
      <geometry>
        <cylinder radius="0.01" length="0.025" />
      </geometry>
    </collision>
  </link>

  <gazebo reference='link_0'>
  <self_collide>0</self_collide>
  <enable_wind>0</enable_wind>
  <kinematic>0</kinematic>
  <collision>
    <laser_retro>0</laser_retro>
    <max_contacts>10</max_contacts>
    <surface>
      <friction>
        <ode>
          <mu>1</mu>
          <mu2>1</mu2>
          <fdir1>0 0 0</fdir1>
          <slip1>0</slip1>
          <slip2>0</slip2>
        </ode>
        <torsional>
          <coefficient>1</coefficient>
          <patch_radius>0</patch_radius>
          <surface_radius>0</surface_radius>
          <use_patch_radius>1</use_patch_radius>
          <ode>
            <slip>0</slip>
          </ode>
        </torsional>
      </friction>
      <bounce>
        <restitution_coefficient>0</restitution_coefficient>
        <threshold>1e+06</threshold>
      </bounce>
      <contact>
        <collide_without_contact>0</collide_without_contact>
        <collide_without_contact_bitmask>1</collide_without_contact_bitmask>
        <collide_bitmask>1</collide_bitmask>
        <ode>
          <soft_cfm>0</soft_cfm>
          <soft_erp>0.2</soft_erp>
          <kp>1e+13</kp>
          <kd>1</kd>
          <max_vel>0.01</max_vel>
          <min_depth>0</min_depth>
        </ode>
        <bullet>
          <split_impulse>1</split_impulse>
          <split_impulse_penetration_threshold>-0.01</split_impulse_penetration_threshold>
          <soft_cfm>0</soft_cfm>
          <soft_erp>0.2</soft_erp>
          <kp>1e+13</kp>
          <kd>1</kd>
        </bullet>
      </contact>
    </surface>
  </collision>
  </gazebo>


<gazebo reference='link_1'>

<collision>
  <laser_retro>0</laser_retro>
  <max_contacts>10</max_contacts>
  <surface>
    <friction>
      <ode>
        <mu>1</mu>
        <mu2>1</mu2>
        <fdir1>0 0 0</fdir1>
        <slip1>0</slip1>
        <slip2>0</slip2>
      </ode>
      <torsional>
        <coefficient>1</coefficient>
        <patch_radius>0</patch_radius>
        <surface_radius>0</surface_radius>
        <use_patch_radius>1</use_patch_radius>
        <ode>
          <slip>0</slip>
        </ode>
      </torsional>
    </friction>
    <bounce>
      <restitution_coefficient>0</restitution_coefficient>
      <threshold>1e+06</threshold>
    </bounce>
    <contact>
      <collide_without_contact>0</collide_without_contact>
      <collide_without_contact_bitmask>1</collide_without_contact_bitmask>
      <collide_bitmask>1</collide_bitmask>
      <ode>
        <soft_cfm>0</soft_cfm>
        <soft_erp>0.2</soft_erp>
        <kp>1e+13</kp>
        <kd>1</kd>
        <max_vel>0.01</max_vel>
        <min_depth>0</min_depth>
      </ode>
      <bullet>
        <split_impulse>1</split_impulse>
        <split_impulse_penetration_threshold>-0.01</split_impulse_penetration_threshold>
        <soft_cfm>0</soft_cfm>
        <soft_erp>0.2</soft_erp>
        <kp>1e+13</kp>
        <kd>1</kd>
      </bullet>
    </contact>
  </surface>
</collision>

</gazebo>

<gazebo reference='link_2'>

<self_collide>0</self_collide>
<enable_wind>0</enable_wind>
<kinematic>0</kinematic>
<gravity>1</gravity>
<collision>
  <laser_retro>0</laser_retro>
  <max_contacts>10</max_contacts>
  <surface>
    <friction>
      <ode>
        <mu>1</mu>
        <mu2>1</mu2>
        <fdir1>0 0 0</fdir1>
        <slip1>0</slip1>
        <slip2>0</slip2>
      </ode>
      <torsional>
        <coefficient>1</coefficient>
        <patch_radius>0</patch_radius>
        <surface_radius>0</surface_radius>
        <use_patch_radius>1</use_patch_radius>
        <ode>
          <slip>0</slip>
        </ode>
      </torsional>
    </friction>
    <bounce>
      <restitution_coefficient>0</restitution_coefficient>
      <threshold>1e+06</threshold>
    </bounce>
    <contact>
      <collide_without_contact>0</collide_without_contact>
      <collide_without_contact_bitmask>1</collide_without_contact_bitmask>
      <collide_bitmask>1</collide_bitmask>
      <ode>
        <soft_cfm>0</soft_cfm>
        <soft_erp>0.2</soft_erp>
        <kp>1e+13</kp>
        <kd>1</kd>
        <max_vel>0.01</max_vel>
        <min_depth>0</min_depth>
      </ode>
      <bullet>
        <split_impulse>1</split_impulse>
        <split_impulse_penetration_threshold>-0.01</split_impulse_penetration_threshold>
        <soft_cfm>0</soft_cfm>
        <soft_erp>0.2</soft_erp>
        <kp>1e+13</kp>
        <kd>1</kd>
      </bullet>
    </contact>
  </surface>
</collision>


</gazebo>

<gazebo reference='link_3'>
<laser_retro>0</laser_retro>
<max_contacts>10</max_contacts>
<self_collide>0</self_collide>
<enable_wind>0</enable_wind>
<kinematic>0</kinematic>
<gravity>1</gravity>
<collision>
  <laser_retro>0</laser_retro>
  <max_contacts>10</max_contacts>
  <surface>
    <friction>
      <ode>
        <mu>1</mu>
        <mu2>1</mu2>
        <fdir1>0 0 0</fdir1>
        <slip1>0</slip1>
        <slip2>0</slip2>
      </ode>
      <torsional>
        <coefficient>1</coefficient>
        <patch_radius>0</patch_radius>
        <surface_radius>0</surface_radius>
        <use_patch_radius>1</use_patch_radius>
        <ode>
          <slip>0</slip>
        </ode>
      </torsional>
    </friction>
    <bounce>
      <restitution_coefficient>0</restitution_coefficient>
      <threshold>1e+06</threshold>
    </bounce>
    <contact>
      <collide_without_contact>0</collide_without_contact>
      <collide_without_contact_bitmask>1</collide_without_contact_bitmask>
      <collide_bitmask>1</collide_bitmask>
      <ode>
        <soft_cfm>0</soft_cfm>
        <soft_erp>0.2</soft_erp>
        <kp>1e+13</kp>
        <kd>1</kd>
        <max_vel>0.01</max_vel>
        <min_depth>0</min_depth>
      </ode>
      <bullet>
        <split_impulse>1</split_impulse>
        <split_impulse_penetration_threshold>-0.01</split_impulse_penetration_threshold>
        <soft_cfm>0</soft_cfm>
        <soft_erp>0.2</soft_erp>
        <kp>1e+13</kp>
        <kd>1</kd>
      </bullet>
    </contact>
  </surface>
</collision>

</gazebo>


<gazebo reference='link_4'>
<self_collide>0</self_collide>
<enable_wind>0</enable_wind>
<kinematic>0</kinematic>
<gravity>1</gravity>

<collision>
  <laser_retro>0</laser_retro>
  <max_contacts>10</max_contacts>
  <surface>
    <friction>
      <ode>
        <mu>1</mu>
        <mu2>1</mu2>
        <fdir1>0 0 0</fdir1>
        <slip1>0</slip1>
        <slip2>0</slip2>
      </ode>
      <torsional>
        <coefficient>1</coefficient>
        <patch_radius>0</patch_radius>
        <surface_radius>0</surface_radius>
        <use_patch_radius>1</use_patch_radius>
        <ode>
          <slip>0</slip>
        </ode>
      </torsional>
    </friction>
    <bounce>
      <restitution_coefficient>0</restitution_coefficient>
      <threshold>1e+06</threshold>
    </bounce>
    <contact>
      <collide_without_contact>0</collide_without_contact>
      <collide_without_contact_bitmask>1</collide_without_contact_bitmask>
      <collide_bitmask>1</collide_bitmask>
      <ode>
        <soft_cfm>0</soft_cfm>
        <soft_erp>0.2</soft_erp>
        <kp>1e+13</kp>
        <kd>1</kd>
        <max_vel>0.01</max_vel>
        <min_depth>0</min_depth>
      </ode>
      <bullet>
        <split_impulse>1</split_impulse>
        <split_impulse_penetration_threshold>-0.01</split_impulse_penetration_threshold>
        <soft_cfm>0</soft_cfm>
        <soft_erp>0.2</soft_erp>
        <kp>1e+13</kp>
        <kd>1</kd>
      </bullet>
    </contact>
  </surface>
</collision>


</gazebo>

<gazebo reference='link_5'>
<self_collide>0</self_collide>
<enable_wind>0</enable_wind>
<kinematic>0</kinematic>
<gravity>1</gravity>

<collision>
  <laser_retro>0</laser_retro>
  <max_contacts>10</max_contacts>
  <surface>
    <friction>
      <ode>
        <mu>1</mu>
        <mu2>1</mu2>
        <fdir1>0 0 0</fdir1>
        <slip1>0</slip1>
        <slip2>0</slip2>
      </ode>
      <torsional>
        <coefficient>1</coefficient>
        <patch_radius>0</patch_radius>
        <surface_radius>0</surface_radius>
        <use_patch_radius>1</use_patch_radius>
        <ode>
          <slip>0</slip>
        </ode>
      </torsional>
    </friction>
    <bounce>
      <restitution_coefficient>0</restitution_coefficient>
      <threshold>1e+06</threshold>
    </bounce>
    <contact>
      <collide_without_contact>0</collide_without_contact>
      <collide_without_contact_bitmask>1</collide_without_contact_bitmask>
      <collide_bitmask>1</collide_bitmask>
      <ode>
        <soft_cfm>0</soft_cfm>
        <soft_erp>0.2</soft_erp>
        <kp>1e+13</kp>
        <kd>1</kd>
        <max_vel>0.01</max_vel>
        <min_depth>0</min_depth>
      </ode>
      <bullet>
        <split_impulse>1</split_impulse>
        <split_impulse_penetration_threshold>-0.01</split_impulse_penetration_threshold>
        <soft_cfm>0</soft_cfm>
        <soft_erp>0.2</soft_erp>
        <kp>1e+13</kp>
        <kd>1</kd>
      </bullet>
    </contact>
  </surface>
</collision>


</gazebo>


<gazebo reference='link_6'>
<self_collide>0</self_collide>
<enable_wind>0</enable_wind>
<kinematic>0</kinematic>
<gravity>1</gravity>

<collision>
  <laser_retro>0</laser_retro>
  <max_contacts>10</max_contacts>
  <surface>
    <friction>
      <ode>
        <mu>1</mu>
        <mu2>1</mu2>
        <fdir1>0 0 0</fdir1>
        <slip1>0</slip1>
        <slip2>0</slip2>
      </ode>
      <torsional>
        <coefficient>1</coefficient>
        <patch_radius>0</patch_radius>
        <surface_radius>0</surface_radius>
        <use_patch_radius>1</use_patch_radius>
        <ode>
          <slip>0</slip>
        </ode>
      </torsional>
    </friction>
    <bounce>
      <restitution_coefficient>0</restitution_coefficient>
      <threshold>1e+06</threshold>
    </bounce>
    <contact>
      <collide_without_contact>0</collide_without_contact>
      <collide_without_contact_bitmask>1</collide_without_contact_bitmask>
      <collide_bitmask>1</collide_bitmask>
      <ode>
        <soft_cfm>0</soft_cfm>
        <soft_erp>0.2</soft_erp>
        <kp>1e+13</kp>
        <kd>1</kd>
        <max_vel>0.01</max_vel>
        <min_depth>0</min_depth>
      </ode>
      <bullet>
        <split_impulse>1</split_impulse>
        <split_impulse_penetration_threshold>-0.01</split_impulse_penetration_threshold>
        <soft_cfm>0</soft_cfm>
        <soft_erp>0.2</soft_erp>
        <kp>1e+13</kp>
        <kd>1</kd>
      </bullet>
    </contact>
  </surface>
</collision>


</gazebo>


<gazebo reference='link_7'>
<self_collide>0</self_collide>
<enable_wind>0</enable_wind>
<kinematic>0</kinematic>
<gravity>1</gravity>

<collision>
  <laser_retro>0</laser_retro>
  <max_contacts>10</max_contacts>
  <surface>
    <friction>
      <ode>
        <mu>1</mu>
        <mu2>1</mu2>
        <fdir1>0 0 0</fdir1>
        <slip1>0</slip1>
        <slip2>0</slip2>
      </ode>
      <torsional>
        <coefficient>1</coefficient>
        <patch_radius>0</patch_radius>
        <surface_radius>0</surface_radius>
        <use_patch_radius>1</use_patch_radius>
        <ode>
          <slip>0</slip>
        </ode>
      </torsional>
    </friction>
    <bounce>
      <restitution_coefficient>0</restitution_coefficient>
      <threshold>1e+06</threshold>
    </bounce>
    <contact>
      <collide_without_contact>0</collide_without_contact>
      <collide_without_contact_bitmask>1</collide_without_contact_bitmask>
      <collide_bitmask>1</collide_bitmask>
      <ode>
        <soft_cfm>0</soft_cfm>
        <soft_erp>0.2</soft_erp>
        <kp>1e+13</kp>
        <kd>1</kd>
        <max_vel>0.01</max_vel>
        <min_depth>0</min_depth>
      </ode>
      <bullet>
        <split_impulse>1</split_impulse>
        <split_impulse_penetration_threshold>-0.01</split_impulse_penetration_threshold>
        <soft_cfm>0</soft_cfm>
        <soft_erp>0.2</soft_erp>
        <kp>1e+13</kp>
        <kd>1</kd>
      </bullet>
    </contact>
  </surface>
</collision>
</gazebo>


  <joint name="joint1" type="revolute">
    <origin xyz="-0.5 0.4 0.0" rpy="0.0 -0.0 0.0" />
    <axis xyz="0.0 0.0 1.0" />
    <parent link="link_0" />
    <child link="link_3" />
    <limit lower="-1.0" upper="0.0" effort="100.0" velocity="inf" />
  </joint>
  <joint name="joint3" type="revolute">
    <origin xyz="-0.8999400000000004 -0.0027720000000006073 -0.339814" rpy="-0.005156 -0.001069 -0.015992" />
    <axis xyz="0.00222029902051 -0.0102940747717 0.999944549611" />
    <parent link="link_3" />
    <child link="link_2" />
    <limit lower="-1.0" upper="1.0" effort="100.0" velocity="inf" />
  </joint>
  <joint name="wheel2" type="revolute">
    <origin xyz="-6.58452630957207e-05 0.00029099656696679466 -0.11271499186620793" rpy="0.00517243793315 0.000986398184442 0.015997306936" />
    <axis xyz="0.0 1.0 0.0" />
    <parent link="link_2" />
    <child link="link_7" />
    <limit lower="-1.79769e+308" upper="1.79769e+308" effort="100.0" velocity="inf" />
  </joint>
  <joint name="joint2" type="revolute">
    <origin xyz="-0.5 -0.4 0.0" rpy="0.0 -0.0 0.0" />
    <axis xyz="0.0 0.0 1.0" />
    <parent link="link_0" />
    <child link="link_4" />
    <limit lower="0.0" upper="1.0" effort="100.0" velocity="inf" />
  </joint>
  <joint name="joint4" type="revolute">
    <origin xyz="-0.89995 -0.00029200000000007 -0.337839" rpy="-0.005156 -0.001069 -0.015992" />
    <axis xyz="0.00222029902051 -0.0102940747717 0.999944549611" />
    <parent link="link_4" />
    <child link="link_1" />
    <limit lower="-1.0" upper="1.0" effort="100.0" velocity="inf" />
  </joint>
  <joint name="wheel1" type="revolute">
    <origin xyz="-5.584654750245832e-05 0.00029115653313510625 -0.11271500173018811" rpy="0.00517243793315 0.000986398184442 0.015997306936" />
    <axis xyz="0.0 1.0 0.0" />
    <parent link="link_1" />
    <child link="link_5" />
    <limit lower="-1.79769e+308" upper="1.79769e+308" effort="100.0" velocity="inf" />
  </joint>
  <joint name="wheel3" type="revolute">
    <origin xyz="0.400113 -0.000583 -0.450616" rpy="0.0 -0.0 0.0" />
    <axis xyz="0.0 1.0 0.0" />
    <parent link="link_0" />
    <child link="link_6" />
    <limit lower="-1.79769e+308" upper="1.79769e+308" effort="100.0" velocity="inf" />
  </joint>


  <gazebo reference='joint1'>

  <axis>
    <dynamics>
      <spring_reference>0</spring_reference>
      <spring_stiffness>0</spring_stiffness>
      <damping>0</damping>
      <friction>0</friction>
    </dynamics>
  </axis>
  <physics>
    <ode>
      <limit>
        <cfm>0</cfm>
        <erp>0.2</erp>
      </limit>
      <suspension>
        <cfm>0</cfm>
        <erp>0.2</erp>
      </suspension>
    </ode>
  </physics>

  </gazebo>

  <gazebo reference='joint2'>

  <axis>
    <dynamics>
      <spring_reference>0</spring_reference>
      <spring_stiffness>0</spring_stiffness>
      <damping>0</damping>
      <friction>0</friction>
    </dynamics>
  </axis>
  <physics>
    <ode>
      <limit>
        <cfm>0</cfm>
        <erp>0.2</erp>
      </limit>
      <suspension>
        <cfm>0</cfm>
        <erp>0.2</erp>
      </suspension>
    </ode>
  </physics>

  </gazebo>

  <gazebo reference='joint3'>

  <axis>
    <dynamics>
      <spring_reference>0</spring_reference>
      <spring_stiffness>0</spring_stiffness>
      <damping>0</damping>
      <friction>0</friction>
    </dynamics>
  </axis>
  <physics>
    <ode>
      <limit>
        <cfm>0</cfm>
        <erp>0.2</erp>
      </limit>
      <suspension>
        <cfm>0</cfm>
        <erp>0.2</erp>
      </suspension>
    </ode>
  </physics>

  </gazebo>

  <gazebo reference='joint4'>

  <axis>
    <dynamics>
      <spring_reference>0</spring_reference>
      <spring_stiffness>0</spring_stiffness>
      <damping>0</damping>
      <friction>0</friction>
    </dynamics>
  </axis>
  <physics>
    <ode>
      <limit>
        <cfm>0</cfm>
        <erp>0.2</erp>
      </limit>
      <suspension>
        <cfm>0</cfm>
        <erp>0.2</erp>
      </suspension>
    </ode>
  </physics>
  </gazebo>

  <ros2_control name="GazeboSystem" type="system">
  <hardware>
    <plugin>gazebo_ros2_control/GazeboSystem</plugin>
  </hardware>

  <joint name="joint1">
    <command_interface name="position">
      <param name="min">-1</param>
      <param name="max">1</param>
    </command_interface>
    <state_interface name="position"/>
    <state_interface name="velocity"/>
    <state_interface name="effort"/>
  </joint>

  <joint name="joint2">
    <command_interface name="position">
      <param name="min">-1</param>
      <param name="max">1</param>
    </command_interface>
    <state_interface name="position"/>
    <state_interface name="velocity"/>
    <state_interface name="effort"/>
  </joint>

  <joint name="joint3">
    <command_interface name="position">
      <param name="min">-1</param>
      <param name="max">1</param>
    </command_interface>
    <state_interface name="position"/>
    <state_interface name="velocity"/>
    <state_interface name="effort"/>
  </joint>

  <joint name="joint4">
    <command_interface name="position">
      <param name="min">-1</param>
      <param name="max">1</param>
    </command_interface>
    <state_interface name="position"/>
    <state_interface name="velocity"/>
    <state_interface name="effort"/>
  </joint>

  <joint name="wheel3">
    <state_interface name="position"/>
    <state_interface name="velocity"/>
    <state_interface name="effort"/>
  </joint>
  </ros2_control>

  <gazebo>
  <plugin filename="libgazebo_ros2_control.so" name="gazebo_ros2_control">
    <parameters>$(find gazebo_ros2_control_demos)/config/test.yaml</parameters>
  </plugin>
  </gazebo>

</robot>
